Workbook
Name agency_price: Financials!$B$8
Name agency_y5: Financials!$B$7
Name brand_price: Financials!$B$6
Name brand_y5: Financials!$B$5
Name CPM_table: Niches!$K$5:$L$24
Name gm: Financials!$B$9
Name init_inv: Financials!$B$14
Name opex_pct: Financials!$B$10
Name SAM_pct: Market_Sizing!$B$11
Name tax: Financials!$B$11
Name term_g: Financials!$B$13
Name tooling_pct: Market_Sizing!$B$12
Name WACC: Financials!$B$12

Sheet Summary
A1: CreatorPulse — Executive Summary
A2: Creator-economy intelligence for India · creators + brands · free-forever OSS stack
A4: Creators indexed | C4: Niches tracked | E4: TAM (₹ cr, 2025) | G4: Year-5 ARR (₹ cr)
A5: =COUNTA(Data!A5:A12551)-0 -> 12547 | C5: =COUNTA(Niches!A5:A24) -> 20 | E5: =Market_Sizing!C5 -> 3400 | G5: =Financials!$B$31/10000000 -> 8.25
A7: Enterprise NPV (₹ cr) | C7: Median fraud risk | E7: Fraud classifier F1 | G7: Match A/B lift
A8: =Financials!$B$35/10000000 -> 7.1110478 | C8: =MEDIAN(Data!F5:F12551) -> 0.0822 | E8: =OKRs!D8 -> 0.83 | G8: =OKRs!D7/100 -> 0.23
A11: Narrative
A12: CreatorPulse indexes 12,547 Indian YouTube creators from the official Data API and layers an XGBoost engagement-fraud classifier, K-means/DBSCAN archetype clustering, a sentence-transformer brand-creator match engine and Prophet niche forecasts on top. Dual-persona product (creators + brands) instrumented in PostHog. Figures trace to the live corpus and market_sizing.md; pre-launch cohort/funnel/A-B numbers are simulated.

Sheet Data
A1: Creator dataset (pivot / lookup source)
A2: 12,547 live Indian YouTube channels · official Data API · fraud_risk = fraud_classifier_v1 P(suspicious)
A4: channel_id | B4: niche | C4: subscriber_count | D4: mean_views | E4: mean_engagement_rate | F4: fraud_risk
A5: UCRm96I5kmb_iGFofE5N691w | B5: Sports | C5: 52800000 | D5: 5522.1 | E5: 0.0185 | F5: 0.1053
A6: UCEKWXRsfUHkan-D_ljU8Asw | B6: Sports | C6: 41200000 | D6: 24342.6 | E6: 0.0074 | F6: 0.0811
A7: UC6-F5tO8uklgE9Zy8IvbdFw | B7: Devotional | C7: 105000000 | D7: 19921.4 | E7: 0.0508 | F7: 0.0938
A8: UC-LPIU24bQXVljUXivKEeRQ | B8: Vlogs | C8: 56600000 | D8: 4326.7 | E8: 0.0738 | F8: 0.2381
A9: UC4DLvb5xZ9OLcVM1KC_R97g | B9: Parenting | C9: 39700000 | D9: 929957.5 | E9: 0.0285 | F9: 0.0409
A10: UCP84QWij0alw4MvzqzyfOnw | B10: Comedy | C10: 34400000 | D10: 782083.7 | E10: 0.0053 | F10: 0.0822
A11: UCLtNvbkqea8wN_kGtfgx_Mw | B11: Music | C11: 34100000 | D11: 23398.1 | E11: 0.0115 | F11: 0.0822
A12: UCN8S4CqMRy6tVKVXvs7Bzeg | B12: Comedy | C12: 41400000 | D12: 29241.6 | E12: 0.0073 | F12: 0.0811
A13: UCF1JIbMUs6uqoZEY1Haw0GQ | B13: Travel | C13: 61800000 | D13: 46907.9 | E13: 0.0105 | F13: 0.0811
A14: UCBOmfqgTZi7yDp4-3Lr_3lA | B14: Sports | C14: 39400000 | D14: 18054.1 | E14: 0.0107 | F14: 0.0811
A15: UC55IWqFLDH1Xp7iu1_xknRA | B15: Sports | C15: 82100000 | D15: 92 | E15: 0.1195 | F15: 0.2059
A16: UC6lVSi_MZ5IZPECkOU0oXoA | B16: Vlogs | C16: 3530000 | D16: 264218.9 | E16: 0.0387 | F16: 0.0409
... A125: UCAXe-dTMWRcqDdt5pYLwHCA | B125: Vlogs | C125: 14300000 | D125: 8137.2 | E125: 0.0008 | F125: 0.0654
A126: UCsgdASJ1gqK_CcEbvaIcFcg | B126: Vlogs | C126: 14900000 | D126: 11139921 | F126: 0.0518
A127: UCPQtgEj6Z0xve62aeSgo5qA | B127: Vlogs | C127: 17200000 | D127: 1694784.5 | E127: 0.021 | F127: 0.1053
A128: UCTbNOCtAGaqOEnLMeo3JTeg | B128: Food | C128: 13500000 | D128: 186503.8 | E128: 0.0311 | F128: 0.0759
A129: UCWKeZvw4iSZVM2qXKZde58A | B129: Parenting | C129: 16500000 | D129: 1972.1 | E129: 0.0051 | F129: 0.0811
A130: UCsCe7SNQckiRJ6y563SIupg | B130: Parenting | C130: 17500000 | D130: 192615.8 | E130: 0.0062 | F130: 0.0811
A131: UC9CYT9gSNLevX5ey2_6CK0Q | B131: News | C131: 25800000 | D131: 5969.9 | E131: 0.0128 | F131: 0.0726
A132: UC3oQ1986eLZ4MhyPBiu54PA | B132: Devotional | C132: 15900000 | D132: 2076.7 | E132: 0.0347 | F132: 0.0938
A133: UCLWCv3y3FK1pqEbe_yzilsw | B133: Music | C133: 20500000 | D133: 93616.3 | E133: 0.0072 | F133: 0.1015
A134: UCVmEbEQUGXHVm-O9pqa3JWg | B134: Vlogs | C134: 16600000 | D134: 7019176.6 | E134: 0.041 | F134: 0.0518
A135: UCCy2rLnGdwoJcSAtixNdsPQ | B135: Sports | C135: 21800000 | D135: 98.7 | E135: 0.0156 | F135: 0.1948
A136: UCEPL07qzVsOcHd3sMUws65g | B136: Tech | C136: 15500000 | D136: 332799.7 | E136: 0.0423 | F136: 0.0938
A137: UCAgAsH5n26IHMDyzwhF3wIw | B137: Vlogs | C137: 17900000 | D137: 1378523.3 | E137: 0.0424 | F137: 0.0409
A138: UC_wIGmvdyAQLtl-U2nHV9rg | B138: Sports | C138: 17800000 | D138: 1291.8 | E138: 0.02 | F138: 0.051
... A222: UC8dnBi4WUErqYQHZ4PfsLTg | B222: News | C222: 12200000 | D222: 3397.5 | E222: 0.0065 | F222: 0.0811
A223: UCEvwoeic0Y4789FXBNCXWeA | B223: Comedy | C223: 10900000 | D223: 21278.5 | F223: 0.0409
A224: UCp_r6Z-Oh0YTf-ym71z5Nqg | B224: Sports | C224: 12500000 | D224: 3971.1 | E224: 0.0236 | F224: 0.0938
A225: UCyLaexBEXMybtK12r386SDw | B225: Vlogs | C225: 10300000 | D225: 636026.5 | E225: 0.0315 | F225: 0.0518
A226: UCRZGmOiXD7DRBG6VPc6KVRQ | B226: Comedy | C226: 12700000 | D226: 15830.9 | E226: 0.0074 | F226: 0.0811
A227: UCTLZ1jlmY-VogpQXng48iKQ | B227: Food | C227: 11200000 | D227: 1685724.4 | E227: 0.0094 | F227: 0.0866
A228: UC4I13pjEDm7rHFMb5PkOUaw | B228: Education | C228: 10900000 | D228: 17219.4 | E228: 0.0493 | F228: 0.0938
A229: UCWEqIFOOjmL_olrETpSnGOQ | B229: Vlogs | C229: 10800000 | D229: 7464022.2 | E229: 0.0499 | F229: 0.0759
A230: UCFk2qpStVlJTkgedostU4kQ | B230: Auto | C230: 9060000 | D230: 5304.8 | E230: 0.0118 | F230: 0.0654
A231: UCfCv0ckR89HTy2ASEgZHNSg | B231: Parenting | C231: 11800000 | D231: 261584.7 | E231: 0.0011 | F231: 0.0822
A232: UCvMd32ON30vh2bd-_A5KA1A | B232: Sports | C232: 16500000 | D232: 679.4 | E232: 0.033 | F232: 0.0938
...

Sheet Market_Sizing
A1: Market Sizing — TAM / SAM / SOM
A2: Indian influencer-marketing opportunity · top-down + bottoms-up cross-check · Source: market_sizing.md (EY/Kofluence/Goat-Kantar 2025)
A4: Layer | B4: Definition | C4: Figure (₹ cr)
A5: TAM | B5: Total Indian influencer-marketing spend (2025, ~25% YoY) | C5: 3400
A6: SAM | B6: Mid-market D2C + independent-agency segment (~15% of TAM) | C6: =C5*SAM_pct -> 510
A7: Tooling-SAM | B7: Software/tooling spend within SAM (4% of campaign spend) | C7: =C6*tooling_pct -> 20.4
A8: SOM | B8: CreatorPulse achievable Year-5 ARR (from Financials) | C8: =Financials!$B$31/10000000 -> 8.25
A10: Assumptions
A11: SAM as % of TAM | B11: 0.15
A12: Tooling as % of SAM | B12: 0.04
A14: Bottoms-up TAM cross-check
A15: Active brands running paid campaigns | B15: 13500
A16: Avg annual influencer budget (₹) | B16: 2500000
A17: Implied TAM (₹ cr) | B17: =B15*B16/10000000 -> 3375

Sheet Financials
A1: 5-Year DCF — Revenue / EBITDA / NPV / IRR
A2: Freemium B2B SaaS · SOM build from market_sizing.md (Year-5: 1,200 brands × ₹50k + 150 agencies × ₹1.5L)
A4: Assumptions (blue = input)
A5: Brand accounts (Yr5) | B5: 1200
A6: Brand price/yr (₹) | B6: 50000
A7: Agency accounts (Yr5) | B7: 150
A8: Agency price/yr (₹) | B8: 150000
A9: Gross margin | B9: 0.82
A10: OpEx % of revenue | B10: 0.55
A11: Tax rate | B11: 0.25
A12: WACC | B12: 0.18
A13: Terminal growth | B13: 0.04
A14: Initial investment (₹) | B14: 5000000
A16: Adoption ramp (% of Yr5) | B16: Y1 | C16: Y2 | D16: Y3 | E16: Y4 | F16: Y5
B17: 0.08 | C17: 0.22 | D17: 0.45 | E17: 0.72 | F17: 1
A19: P&L build (₹)
A20: Year | B20: Y1 | C20: Y2 | D20: Y3 | E20: Y4 | F20: Y5
A21: Brand accounts | B21: =ROUND(brand_y5*B17,0) -> 96 | C21: =ROUND(brand_y5*C17,0) -> 264 | D21: =ROUND(brand_y5*D17,0) -> 540 | E21: =ROUND(brand_y5*E17,0) -> 864 | F21: =ROUND(brand_y5*F17,0) -> 1200
A22: Agency accounts | B22: =ROUND(agency_y5*B17,0) -> 12 | C22: =ROUND(agency_y5*C17,0) -> 33 | D22: =ROUND(agency_y5*D17,0) -> 68 | E22: =ROUND(agency_y5*E17,0) -> 108 | F22: =ROUND(agency_y5*F17,0) -> 150
A23: Revenue | B23: =B21*brand_price+B22*agency_price -> 6600000 | C23: =C21*brand_price+C22*agency_price -> 18150000 | D23: =D21*brand_price+D22*agency_price -> 37200000 | E23: =E21*brand_price+E22*agency_price -> 59400000 | F23: =F21*brand_price+F22*agency_price -> 82500000
A24: Gross profit | B24: =B23*gm -> 5412000 | C24: =C23*gm -> 14883000 | D24: =D23*gm -> 30504000 | E24: =E23*gm -> 48708000 | F24: =F23*gm -> 67650000
A25: OpEx | B25: =B23*opex_pct -> 3630000 | C25: =C23*opex_pct -> 9982500 | D25: =D23*opex_pct -> 20460000 | E25: =E23*opex_pct -> 32670000 | F25: =F23*opex_pct -> 45375000
A26: EBITDA | B26: =B24-B25 -> 1782000 | C26: =C24-C25 -> 4900500 | D26: =D24-D25 -> 10044000 | E26: =E24-E25 -> 16038000 | F26: =F24-F25 -> 22275000
A27: Tax | B27: =MAX(B26,0)*tax -> 445500 | C27: =MAX(C26,0)*tax -> 1225125 | D27: =MAX(D26,0)*tax -> 2511000 | E27: =MAX(E26,0)*tax -> 4009500 | F27: =MAX(F26,0)*tax -> 5568750
A28: FCF | B28: =B26-B27 -> 1336500 | C28: =C26-C27 -> 3675375 | D28: =D26-D27 -> 7533000 | E28: =E26-E27 -> 12028500 | F28: =F26-F27 -> 16706250
A30: Valuation
A31: Year-5 ARR (₹) | B31: =F23 -> 82500000
A32: Terminal value (₹) | B32: =F28*(1+term_g)/(WACC-term_g) -> 1.2410357e+08
A33: NPV of FCF (₹) | B33: =NPV(WACC,B28:F28) -> 21863663
A34: PV of terminal (₹) | B34: =B32/(1+WACC)^5 -> 54246815
A35: Enterprise NPV (₹) | B35: =B33+B34-init_inv -> 71110478
A36: IRR | B36: =IFERROR(IRR(B38:G38),0) -> 1.2368583
A37: XNPV (dated) | B37: =IFERROR(XNPV(WACC,B38:G38,B39:G39),0) -> 71077682
A38: Cashflow (incl. Y0) | B38: =-init_inv -> -5000000 | C38: =B28 -> 1336500 | D38: =C28 -> 3675375 | E38: =D28 -> 7533000 | F38: =E28 -> 12028500 | G38: =F28+B32 -> 1.4080982e+08
A39: Cashflow dates | B39: 45747 | C39: 46112 | D39: 46477 | E39: 46843 | F39: 47208 | G39: 47573
A41: NPV sensitivity to WACC
B42: 0.14 | C42: 0.16 | D42: 0.18 | E42: 0.2 | F42: 0.22
A43: Enterprise NPV (₹) | B43: =NPV(B42,B28:F28)+(F28*(1+term_g)/(B42-term_g))/(1+B42)^5-init_inv -> 1.1012126e+08 | C43: =NPV(C42,B28:F28)+(F28*(1+term_g)/(C42-term_g))/(1+C42)^5-init_inv -> 87242142 | D43: =NPV(D42,B28:F28)+(F28*(1+term_g)/(D42-term_g))/(1+D42)^5-init_inv -> 71110478 | E43: =NPV(E42,B28:F28)+(F28*(1+term_g)/(E42-term_g))/(1+E42)^5-init_inv -> 59180254 | F43: =NPV(F42,B28:F28)+(F28*(1+term_g)/(F42-term_g))/(1+F42)^5-init_inv -> 50038445

Sheet Scenarios
A1: Scenarios — Year-5 ARR sensitivity
A2: Two-variable grid: paid-conversion (adoption) × take-rate (price). Live formulas (base / bull / bear).
A4: Adoption ↓ / Take-rate → | B4: 0.8 | C4: 0.9 | D4: 1 | E4: 1.1 | F4: 1.2
A5: 0.6 | B5: =(brand_y5*$A5*brand_price*B$4)+(agency_y5*$A5*agency_price*B$4) -> 39600000 | C5: =(brand_y5*$A5*brand_price*C$4)+(agency_y5*$A5*agency_price*C$4) -> 44550000 | D5: =(brand_y5*$A5*brand_price*D$4)+(agency_y5*$A5*agency_price*D$4) -> 49500000 | E5: =(brand_y5*$A5*brand_price*E$4)+(agency_y5*$A5*agency_price*E$4) -> 54450000 | F5: =(brand_y5*$A5*brand_price*F$4)+(agency_y5*$A5*agency_price*F$4) -> 59400000
A6: 0.8 | B6: =(brand_y5*$A6*brand_price*B$4)+(agency_y5*$A6*agency_price*B$4) -> 52800000 | C6: =(brand_y5*$A6*brand_price*C$4)+(agency_y5*$A6*agency_price*C$4) -> 59400000 | D6: =(brand_y5*$A6*brand_price*D$4)+(agency_y5*$A6*agency_price*D$4) -> 66000000 | E6: =(brand_y5*$A6*brand_price*E$4)+(agency_y5*$A6*agency_price*E$4) -> 72600000 | F6: =(brand_y5*$A6*brand_price*F$4)+(agency_y5*$A6*agency_price*F$4) -> 79200000
A7: 1 | B7: =(brand_y5*$A7*brand_price*B$4)+(agency_y5*$A7*agency_price*B$4) -> 66000000 | C7: =(brand_y5*$A7*brand_price*C$4)+(agency_y5*$A7*agency_price*C$4) -> 74250000 | D7: =(brand_y5*$A7*brand_price*D$4)+(agency_y5*$A7*agency_price*D$4) -> 82500000 | E7: =(brand_y5*$A7*brand_price*E$4)+(agency_y5*$A7*agency_price*E$4) -> 90750000 | F7: =(brand_y5*$A7*brand_price*F$4)+(agency_y5*$A7*agency_price*F$4) -> 99000000
A8: 1.2 | B8: =(brand_y5*$A8*brand_price*B$4)+(agency_y5*$A8*agency_price*B$4) -> 79200000 | C8: =(brand_y5*$A8*brand_price*C$4)+(agency_y5*$A8*agency_price*C$4) -> 89100000 | D8: =(brand_y5*$A8*brand_price*D$4)+(agency_y5*$A8*agency_price*D$4) -> 99000000 | E8: =(brand_y5*$A8*brand_price*E$4)+(agency_y5*$A8*agency_price*E$4) -> 108900000 | F8: =(brand_y5*$A8*brand_price*F$4)+(agency_y5*$A8*agency_price*F$4) -> 118800000
A9: 1.4 | B9: =(brand_y5*$A9*brand_price*B$4)+(agency_y5*$A9*agency_price*B$4) -> 92400000 | C9: =(brand_y5*$A9*brand_price*C$4)+(agency_y5*$A9*agency_price*C$4) -> 103950000 | D9: =(brand_y5*$A9*brand_price*D$4)+(agency_y5*$A9*agency_price*D$4) -> 115500000 | E9: =(brand_y5*$A9*brand_price*E$4)+(agency_y5*$A9*agency_price*E$4) -> 1.2705e+08 | F9: =(brand_y5*$A9*brand_price*F$4)+(agency_y5*$A9*agency_price*F$4) -> 138600000
A11: Base = adoption 100%, take-rate 100% (centre cell). Bull = 140%/120%. Bear = 60%/80%.

Sheet Niches
A1: Niche Analytics
A2: Per-niche aggregates over the live corpus (AVERAGEIF/COUNTIF on Data) · demand slope from Prophet niche_forecast_v1 · est. CPM via VLOOKUP
A4: Niche | B4: Channels | C4: Mean subs | D4: Mean views | E4: Avg engagement | F4: Avg fraud risk | G4: Avg est. cost (₹) | H4: CPM (₹) | I4: Demand slope | K4: niche | L4: CPM (₹) | N4: Row Labels | O4: Average of Demand slope | P4: Sum of Channels
A5: Auto | B5: =COUNTIF(Data!B:B,A5) -> 405 | C5: =AVERAGEIF(Data!B:B,A5,Data!C:C) -> 624439.75 | D5: =AVERAGEIF(Data!B:B,A5,Data!D:D) -> 274826.77 | E5: =AVERAGEIF(Data!B:B,A5,Data!E:E) -> 0.03135202 | F5: =AVERAGEIF(Data!B:B,A5,Data!F:F) -> 0.087922963 | G5: =D5*H5*20/1000 -> 137413.39 | H5: =VLOOKUP(A5,CPM_table,2,FALSE()) -> 25 | I5: 9.0117023 | K5: Auto | L5: 25 | N5: Auto | O5: 9.0117023 | P5: 405
A6: Beauty | B6: =COUNTIF(Data!B:B,A6) -> 239 | C6: =AVERAGEIF(Data!B:B,A6,Data!C:C) -> 959042.26 | D6: =AVERAGEIF(Data!B:B,A6,Data!D:D) -> 210792.64 | E6: =AVERAGEIF(Data!B:B,A6,Data!E:E) -> 0.026629825 | F6: =AVERAGEIF(Data!B:B,A6,Data!F:F) -> 0.087108368 | G6: =D6*H6*20/1000 -> 105396.32 | H6: =VLOOKUP(A6,CPM_table,2,FALSE()) -> 25 | I6: 267.37454 | K6: Beauty | L6: 25 | N6: Beauty | O6: 267.37454 | P6: 239
A7: Comedy | B7: =COUNTIF(Data!B:B,A7) -> 271 | C7: =AVERAGEIF(Data!B:B,A7,Data!C:C) -> 3648357.6 | D7: =AVERAGEIF(Data!B:B,A7,Data!D:D) -> 1680177.3 | E7: =AVERAGEIF(Data!B:B,A7,Data!E:E) -> 0.026183333 | F7: =AVERAGEIF(Data!B:B,A7,Data!F:F) -> 0.08067048 | G7: =D7*H7*20/1000 -> 840088.65 | H7: =VLOOKUP(A7,CPM_table,2,FALSE()) -> 25 | I7: -111872.09 | K7: Comedy | L7: 25 | N7: Comedy | O7: -111872.09 | P7: 271
A8: DIY | B8: =COUNTIF(Data!B:B,A8) -> 608 | C8: =AVERAGEIF(Data!B:B,A8,Data!C:C) -> 863902.8 | D8: =AVERAGEIF(Data!B:B,A8,Data!D:D) -> 124468.71 | E8: =AVERAGEIF(Data!B:B,A8,Data!E:E) -> 0.025718868 | F8: =AVERAGEIF(Data!B:B,A8,Data!F:F) -> 0.087609868 | G8: =D8*H8*20/1000 -> 62234.355 | H8: =VLOOKUP(A8,CPM_table,2,FALSE()) -> 25 | I8: 473.97034 | K8: DIY | L8: 25 | N8: Devotional | O8: -349.23325 | P8: 787
A9: Devotional | B9: =COUNTIF(Data!B:B,A9) -> 787 | C9: =AVERAGEIF(Data!B:B,A9,Data!C:C) -> 1858022.7 | D9: =AVERAGEIF(Data!B:B,A9,Data!D:D) -> 380090.68 | E9: =AVERAGEIF(Data!B:B,A9,Data!E:E) -> 0.035539532 | F9: =AVERAGEIF(Data!B:B,A9,Data!F:F) -> 0.093812961 | G9: =D9*H9*20/1000 -> 190045.34 | H9: =VLOOKUP(A9,CPM_table,2,FALSE()) -> 25 | I9: -349.23325 | K9: Devotional | L9: 25 | N9: DIY | O9: 473.97034 | P9: 608
A10: Education | B10: =COUNTIF(Data!B:B,A10) -> 1438 | C10: =AVERAGEIF(Data!B:B,A10,Data!C:C) -> 815621.28 | D10: =AVERAGEIF(Data!B:B,A10,Data!D:D) -> 43523.686 | E10: =AVERAGEIF(Data!B:B,A10,Data!E:E) -> 0.04191447 | F10: =AVERAGEIF(Data!B:B,A10,Data!F:F) -> 0.0985242 | G10: =D10*H10*20/1000 -> 30466.58 | H10: =VLOOKUP(A10,CPM_table,2,FALSE()) -> 35 | I10: 2.4033114 | K10: Education | L10: 35 | N10: Education | O10: 2.4033114 | P10: 1438
A11: Fashion | B11: =COUNTIF(Data!B:B,A11) -> 107 | C11: =AVERAGEIF(Data!B:B,A11,Data!C:C) -> 679602.8 | D11: =AVERAGEIF(Data!B:B,A11,Data!D:D) -> 72724.791 | E11: =AVERAGEIF(Data!B:B,A11,Data!E:E) -> 0.022504902 | F11: =AVERAGEIF(Data!B:B,A11,Data!F:F) -> 0.077318692 | G11: =D11*H11*20/1000 -> 36362.395 | H11: =VLOOKUP(A11,CPM_table,2,FALSE()) -> 25 | I11: 331.05798 | K11: Fashion | L11: 25 | N11: Fashion | O11: 331.05798 | P11: 107
A12: Finance | B12: =COUNTIF(Data!B:B,A12) -> 652 | C12: =AVERAGEIF(Data!B:B,A12,Data!C:C) -> 847528.22 | D12: =AVERAGEIF(Data!B:B,A12,Data!D:D) -> 75220.035 | E12: =AVERAGEIF(Data!B:B,A12,Data!E:E) -> 0.042335852 | F12: =AVERAGEIF(Data!B:B,A12,Data!F:F) -> 0.094463957 | G12: =D12*H12*20/1000 -> 120352.06 | H12: =VLOOKUP(A12,CPM_table,2,FALSE()) -> 80 | I12: 234.7611 | K12: Finance | L12: 80 | N12: Finance | O12: 234.7611 | P12: 652
A13: Fitness | B13: =COUNTIF(Data!B:B,A13) -> 470 | C13: =AVERAGEIF(Data!B:B,A13,Data!C:C) -> 1075687.9 | D13: =AVERAGEIF(Data!B:B,A13,Data!D:D) -> 122947.82 | E13: =AVERAGEIF(Data!B:B,A13,Data!E:E) -> 0.033546696 | F13: =AVERAGEIF(Data!B:B,A13,Data!F:F) -> 0.083788085 | G13: =D13*H13*20/1000 -> 61473.909 | H13: =VLOOKUP(A13,CPM_table,2,FALSE()) -> 25 | I13: -498.61655 | K13: Fitness | L13: 25 | N13: Fitness | O13: -498.61655 | P13: 470
A14: Food | B14: =COUNTIF(Data!B:B,A14) -> 812 | C14: =AVERAGEIF(Data!B:B,A14,Data!C:C) -> 1176582.9 | D14: =AVERAGEIF(Data!B:B,A14,Data!D:D) -> 116547.08 | E14: =AVERAGEIF(Data!B:B,A14,Data!E:E) -> 0.024780385 | F14: =AVERAGEIF(Data!B:B,A14,Data!F:F) -> 0.085919089 | G14: =D14*H14*20/1000 -> 58273.539 | H14: =VLOOKUP(A14,CPM_table,2,FALSE()) -> 25 | I14: 6593.672 | K14: Food | L14: 25 | N14: Food | O14: 6593.672 | P14: 812
A15: Gaming | B15: =COUNTIF(Data!B:B,A15) -> 534 | C15: =AVERAGEIF(Data!B:B,A15,Data!C:C) -> 1939370.8 | D15: =AVERAGEIF(Data!B:B,A15,Data!D:D) -> 272397.59 | E15: =AVERAGEIF(Data!B:B,A15,Data!E:E) -> 0.0422688 | F15: =AVERAGEIF(Data!B:B,A15,Data!F:F) -> 0.089179588 | G15: =D15*H15*20/1000 -> 108959.04 | H15: =VLOOKUP(A15,CPM_table,2,FALSE()) -> 20 | I15: -12701.652 | K15: Gaming | L15: 20 | N15: Gaming | O15: -12701.652 | P15: 534
A16: Lifestyle | B16: =COUNTIF(Data!B:B,A16) -> 236 | C16: =AVERAGEIF(Data!B:B,A16,Data!C:C) -> 868858.47 | D16: =AVERAGEIF(Data!B:B,A16,Data!D:D) -> 55356.42 | E16: =AVERAGEIF(Data!B:B,A16,Data!E:E) -> 0.026495556 | F16: =AVERAGEIF(Data!B:B,A16,Data!F:F) -> 0.092983051 | G16: =D16*H16*20/1000 -> 27678.21 | H16: =VLOOKUP(A16,CPM_table,2,FALSE()) -> 25 | I16: -4.6850207 | K16: Lifestyle | L16: 25 | N16: Lifestyle | O16: -4.6850207 | P16: 236
... A24: Vlogs | B24: =COUNTIF(Data!B:B,A24) -> 3459 | C24: =AVERAGEIF(Data!B:B,A24,Data!C:C) -> 1559683.8 | D24: =AVERAGEIF(Data!B:B,A24,Data!D:D) -> 301926.56 | E24: =AVERAGEIF(Data!B:B,A24,Data!E:E) -> 0.03441908 | F24: =AVERAGEIF(Data!B:B,A24,Data!F:F) -> 0.084060653 | G24: =D24*H24*20/1000 -> 150963.28 | H24: =VLOOKUP(A24,CPM_table,2,FALSE()) -> 25 | I24: 283.57584 | K24: Vlogs | L24: 25 | N24: Vlogs | O24: 283.57584 | P24: 3459
N25: Grand Total | O25: -5816.7786 | P25: 12547
A26: Fastest-growing niche (INDEX/MATCH on slope): | D26: =INDEX(A5:A24,MATCH(MAX(I5:I24),I5:I24,0)) -> Food
A27: Highest avg fraud risk (INDEX/MATCH): | D27: =INDEX(A5:A24,MATCH(MAX(F5:F24),F5:F24,0)) -> News

Sheet Fraud_Stats
A1: Engagement-Risk Distribution & False-Positive Cost
A2: fraud_risk = XGBoost fraud_classifier_v1 P(suspicious) over 12,547 live channels (model validated on a simulated cohort).
A4: Risk band | B4: Lower | C4: Upper | D4: Channels | E4: % of corpus | G4: Row Labels | H4: Sum of Channels | I4: Average of % of corpus
A5: Very low | B5: 0 | C5: 0.05 | D5: =COUNTIFS(Data!F:F,">="&B5,Data!F:F,"<"&C5) -> 1161 | E5: =D5/SUM($D$5:$D$10) -> 0.092532079 | G5: Elevated | H5: 189 | I5: 0.015063362
A6: Low | B6: 0.05 | C6: 0.1 | D6: =COUNTIFS(Data!F:F,">="&B6,Data!F:F,"<"&C6) -> 9238 | E6: =D6/SUM($D$5:$D$10) -> 0.73627162 | G6: High | H6: 148 | I6: 0.011795648
A7: Moderate | B7: 0.1 | C7: 0.2 | D7: =COUNTIFS(Data!F:F,">="&B7,Data!F:F,"<"&C7) -> 1751 | E7: =D7/SUM($D$5:$D$10) -> 0.13955527 | G7: Low | H7: 9238 | I7: 0.73627162
A8: Elevated | B8: 0.2 | C8: 0.3 | D8: =COUNTIFS(Data!F:F,">="&B8,Data!F:F,"<"&C8) -> 189 | E8: =D8/SUM($D$5:$D$10) -> 0.015063362 | G8: Moderate | H8: 1751 | I8: 0.13955527
A9: High | B9: 0.3 | C9: 0.5 | D9: =COUNTIFS(Data!F:F,">="&B9,Data!F:F,"<"&C9) -> 148 | E9: =D9/SUM($D$5:$D$10) -> 0.011795648 | G9: Severe | H9: 60 | I9: 0.0047820196
A10: Severe | B10: 0.5 | C10: 1.01 | D10: =COUNTIFS(Data!F:F,">="&B10,Data!F:F,"<"&C10) -> 60 | E10: =D10/SUM($D$5:$D$10) -> 0.0047820196 | G10: Total | H10: 12547
A11: Total | D11: =SUM(D5:D10) -> 12547 | G11: Very low | H11: 1161 | I11: 0.092532079
G12: Grand Total | H12: 25094 | I12: 0.16666667
A13: False-positive cost analysis
A14: Assumptions
A15: Est. true-fraud prevalence | B15: 0.04
A16: Cost per false flag (lost deal, ₹) | B16: 80000
A18: Flag threshold | B18: Flagged channels | C18: Est. false positives | D18: FP cost (₹)
A19: 0.2 | B19: =COUNTIF(Data!F:F,">="&A19) -> 397 | C19: =B19*(1-$B$15) -> 381.12 | D19: =C19*$B$16 -> 30489600
A20: 0.3 | B20: =COUNTIF(Data!F:F,">="&A20) -> 208 | C20: =B20*(1-$B$15) -> 199.68 | D20: =C20*$B$16 -> 15974400
A21: 0.5 | B21: =COUNTIF(Data!F:F,">="&A21) -> 60 | C21: =B21*(1-$B$15) -> 57.6 | D21: =C21*$B$16 -> 4608000

Sheet Cohorts
A1: Retention Cohorts (PostHog)
A2: Weekly-returning cohorts + persona power users. SIMULATED cohort — pre-launch, no organic traffic (per §18 taxonomy).
A4: Weekly cohort | B4: Week 0 | C4: W1 | D4: W2 | E4: W4 | F4: W1 retention | G4: W4 retention | J4: Row Labels | K4: Sum of W1 | L4: Sum of W4 | M4: Sum of Week 0 | N4: Sum of W2
A5: 2025-W01 | B5: 520 | C5: 198 | D5: 150 | E5: 96 | F5: =C5/B5 -> 0.38076923 | G5: =E5/B5 -> 0.18461538 | J5: 2025-W01 | K5: 198 | L5: 96 | M5: 520 | N5: 150
A6: 2025-W02 | B6: 610 | C6: 232 | D6: 171 | E6: 108 | F6: =C6/B6 -> 0.38032787 | G6: =E6/B6 -> 0.17704918 | J6: 2025-W02 | K6: 232 | L6: 108 | M6: 610 | N6: 171
A7: 2025-W03 | B7: 565 | C7: 221 | D7: 160 | E7: 101 | F7: =C7/B7 -> 0.39115044 | G7: =E7/B7 -> 0.17876106 | J7: 2025-W03 | K7: 221 | L7: 101 | M7: 565 | N7: 160
A8: 2025-W04 | B8: 640 | C8: 256 | D8: 189 | E8: 121 | F8: =C8/B8 -> 0.4 | G8: =E8/B8 -> 0.1890625 | J8: 2025-W04 | K8: 256 | L8: 121 | M8: 640 | N8: 189
J9: Grand Total | K9: 907 | L9: 426 | M9: 2335 | N9: 670
A10: Behavioural cohorts (30d)
A11: Cohort | B11: Users | C11: Share of active
A12: Brand power users (5+ briefs) | B12: 84 | C12: =B12/SUM($B$12:$B$15) -> 0.054794521
A13: Creator power users (3+ chart views) | B13: 212 | C13: =B13/SUM($B$12:$B$15) -> 0.13829093
A14: Multi-persona users | B14: 47 | C14: =B14/SUM($B$12:$B$15) -> 0.030658839
A15: Single-session | B15: 1190 | C15: =B15/SUM($B$12:$B$15) -> 0.77625571

Sheet Funnel
A1: Conversion Funnels (dual persona)
A2: North Star = weekly matched campaigns (brand sessions with ≥1 shortlist). SIMULATED — pre-launch (per §18 funnels).
A4: Brand funnel step | B4: Users | C4: Step conv. | D4: Cum. conv. | F4: Row Labels | G4: Sum of Users | H4: Average of Step conv. | I4: Average of Cum. conv.
A5: persona_selected (brand) | B5: 1000 | C5: =1 -> 1 | D5: =B5/$B$5 -> 1 | F5: brief_composed | G5: 640 | H5: 0.64 | I5: 0.64
A6: brief_composed | B6: 640 | C6: =B6/B5 -> 0.64 | D6: =B6/$B$5 -> 0.64 | F6: comparison_viewed | G6: 190 | H6: 0.57575758 | I6: 0.19
A7: match_requested | B7: 520 | C7: =B7/B6 -> 0.8125 | D7: =B7/$B$5 -> 0.52 | F7: creator_shortlisted | G7: 330 | H7: 0.63461538 | I7: 0.33
A8: creator_shortlisted | B8: 330 | C8: =B8/B7 -> 0.63461538 | D8: =B8/$B$5 -> 0.33 | F8: match_requested | G8: 520 | H8: 0.8125 | I8: 0.52
A9: comparison_viewed | B9: 190 | C9: =B9/B8 -> 0.57575758 | D9: =B9/$B$5 -> 0.19 | F9: persona_selected (brand) | G9: 1000 | H9: 1 | I9: 1
F10: Grand Total | G10: 2680 | H10: 0.73257459 | I10: 0.536
A11: Creator funnel step | B11: Users | C11: Step conv. | D11: Cum. conv.
A12: persona_selected (creator) | B12: 1400 | C12: =1 -> 1 | D12: =B12/$B$12 -> 1
A13: creator_searched | B13: 980 | C13: =B13/B12 -> 0.7 | D13: =B13/$B$12 -> 0.7
A14: creator_profile_viewed | B14: 710 | C14: =B14/B13 -> 0.7244898 | D14: =B14/$B$12 -> 0.50714286
A15: niche_demand_chart_viewed | B15: 430 | C15: =B15/B14 -> 0.6056338 | D15: =B15/$B$12 -> 0.30714286
A17: North Star — weekly matched campaigns | B17: =B8 -> 330

Sheet Competitive
A1: Competitive Teardown — weighted scoring
A2: CreatorPulse vs incumbents. Weighted score = SUMPRODUCT(weights, scores). Scores 1–5; see docs/business/competitive_analysis.md.
A4: Criterion | B4: Weight | C4: CreatorPulse | D4: HypeAuditor | E4: AnyTag | F4: BizFluence | G4: IndianInfluencer
A5: Mid-market pricing | B5: 0.22 | C5: 5 | D5: 2 | E5: 3 | F5: 4 | G5: 4
A6: Fraud / engagement screening | B6: 0.2 | C6: 5 | D6: 5 | E6: 4 | F6: 2 | G6: 2
A7: Creator-side product | B7: 0.15 | C7: 5 | D7: 2 | E7: 2 | F7: 3 | G7: 2
A8: India-specific data | B8: 0.18 | C8: 5 | D8: 3 | E8: 3 | F8: 4 | G8: 5
A9: Discovery + match quality | B9: 0.15 | C9: 4 | D9: 4 | E9: 4 | F9: 3 | G9: 2
A10: Ease of use | B10: 0.1 | C10: 4 | D10: 3 | E10: 4 | F10: 3 | G10: 3
A11: Weighted score | B11: =SUM(B5:B10) -> 1 | C11: =SUMPRODUCT($B$5:$B$10,C5:C10) -> 4.75 | D11: =SUMPRODUCT($B$5:$B$10,D5:D10) -> 3.18 | E11: =SUMPRODUCT($B$5:$B$10,E5:E10) -> 3.3 | F11: =SUMPRODUCT($B$5:$B$10,F5:F10) -> 3.2 | G11: =SUMPRODUCT($B$5:$B$10,G5:G10) -> 3.08

Sheet OKRs
A1: Q1 OKRs
A2: Objective → key results with completion % and traffic-light status.
A4: Objective | B4: Key result | C4: Target | D4: Actual | E4: Completion | F4: Status
A5: Ship dual-persona product | B5: Creator + brand flows live | C5: 2 | D5: 2 | E5: =MIN(D5/C5,1.5) -> 1 | F5: =IF(E5>=1,"On track",IF(E5>=0.7,"At risk","Behind")) -> On track
A6: Index the Indian creator graph | B6: Channels indexed | C6: 10000 | D6: 12547 | E6: =MIN(D6/C6,1.5) -> 1.2547 | F6: =IF(E6>=1,"On track",IF(E6>=0.7,"At risk","Behind")) -> On track
A7: Trustworthy matching | B7: Match-ranking A/B lift (%) | C7: 15 | D7: 23 | E7: =MIN(D7/C7,1.5) -> 1.5 | F7: =IF(E7>=1,"On track",IF(E7>=0.7,"At risk","Behind")) -> On track
A8: Model quality | B8: Fraud classifier F1 | C8: 0.8 | D8: 0.83 | E8: =MIN(D8/C8,1.5) -> 1.0375 | F8: =IF(E8>=1,"On track",IF(E8>=0.7,"At risk","Behind")) -> On track
A9: Forecast coverage | B9: Niches with 12-wk forecast | C9: 20 | D9: 20 | E9: =MIN(D9/C9,1.5) -> 1 | F9: =IF(E9>=1,"On track",IF(E9>=0.7,"At risk","Behind")) -> On track
A10: Analytics instrumentation | B10: PostHog events live | C10: 10 | D10: 12 | E10: =MIN(D10/C10,1.5) -> 1.2 | F10: =IF(E10>=1,"On track",IF(E10>=0.7,"At risk","Behind")) -> On track
